<?xml version="1.0"?>
<!-- created with Phobos 0.7 -->
  <robot name="dbw_mkz" xmlns:xacro="http://www.ros.org/wiki/xacro">
    <xacro:include filename="$(find model_description)/urdf/materials.xacro" />
    <xacro:include filename="$(find model_description)/urdf/model.gazebo" />
    <xacro:include filename="$(find model_description)/urdf/model.trans" />
    <link name="base_footprint">
    </link>

    <link name="base_link">
      <inertial>
        <origin xyz="1.4225 0 0.25" rpy="0 0 0"/>
        <mass value="0.2"/>
        <inertia ixx="0.1" ixy="0.0" ixz="0.0" iyy="0.1" iyz="0.0" izz="0.1"/>
      </inertial>
      <visual name="chassis">
        <origin xyz="1.3641 0 -0.33" rpy="0 0 1.570796"/>
        <geometry>
          <mesh filename="$(find model_description)/meshes/mkz_13/body/body.dae" scale="0.38 0.394 0.394"/>
        </geometry>
        <material name="black.001"/>
      </visual>
      <collision name="chassis_collision">
        <origin xyz="1.51 -0.03046 0.350609" rpy="1.570796 0 -3.141593"/>
        <geometry>
          <mesh filename="package://model_description/meshes/body_collision.stl" scale="0.001 0.001 0.001"/>
        </geometry>
      </collision>
    </link>

    <link name="steer_fl">
      <inertial>
        <origin xyz="-0.013054 -0.0295 0" rpy="0 0 0"/>
        <mass value="1.0"/>
        <inertia ixx="0.037227" ixy="0" ixz="0" iyy="0.04" iyz="0" izz="0.06"/>
      </inertial>
    </link>

    <link name="steer_fr">
      <inertial>
        <origin xyz="-0.01305 0.0275 0" rpy="0 0 0"/>
        <mass value="1.0"/>
        <inertia ixx="0.037227" ixy="0" ixz="0" iyy="0.04" iyz="0" izz="0.06"/>
      </inertial>
    </link>

    <link name="wheel_fl">
      <inertial>
        <origin xyz="0 0 0" rpy="0 -3.141593 0"/>
        <mass value="10.0"/>
        <inertia ixx="0.305583" ixy="0" ixz="0" iyy="0.305583" iyz="0" izz="0.5445"/>
      </inertial>
      <visual name="wheel_fl_visual">
        <origin xyz="0 0 0.0385" rpy="-1.570796 -1.570796 0"/>
        <geometry>
          <mesh filename="package://model_description/meshes/mkz_13/wheel.dae" scale="0.01 0.01 0.01"/>
        </geometry>
        <material name="carpaint_002"/>
      </visual>
      <collision name="wheel_fl_collision">
        <origin xyz="0 0 0" rpy="0 -3.141593 0"/>
        <geometry>
          <cylinder radius="0.33" length="0.2"/>
        </geometry>
      </collision>
    </link>

    <link name="wheel_fr">
      <inertial>
        <origin xyz="0 0 0" rpy="0 3.141593 0"/>
        <mass value="10.0"/>
        <inertia ixx="0.305583" ixy="0" ixz="0" iyy="0.305583" iyz="0" izz="0.5445"/>
      </inertial>
      <visual name="wheel_fr_visual">
        <origin xyz="0 0 -0.043777" rpy="-1.570796 1.570796 0"/>
        <geometry>
          <mesh filename="package://model_description/meshes/mkz_13/wheel.dae" scale="0.01 0.01 0.01"/>
        </geometry>
        <material name="carpaint_002.001"/>
      </visual>
      <collision name="wheel_fr_collision">
        <origin xyz="0 0 -0.0035" rpy="0 3.141593 0"/>
        <geometry>
          <cylinder radius="0.33" length="0.2"/>
        </geometry>
      </collision>
    </link>

    <link name="wheel_rl">
      <inertial>
        <origin xyz="0 0 0" rpy="0 3.141593 0"/>
        <mass value="10.0"/>
        <inertia ixx="0.305583" ixy="0" ixz="0" iyy="0.305583" iyz="0" izz="0.5445"/>
      </inertial>
      <visual name="wheel_rl_visual">
        <origin xyz="0 0 0.017382" rpy="-1.570796 -1.570796 0"/>
        <geometry>
          <mesh filename="package://model_description/meshes/mkz_13/wheel.dae" scale="0.01 0.01 0.01"/>
        </geometry>
        <material name="carpaint_002.003"/>
      </visual>
      <collision name="wheel_rl_collision">
        <origin xyz="0 0 -0.021118" rpy="0 3.141593 0"/>
        <geometry>
          <cylinder radius="0.33" length="0.2"/>
        </geometry>
      </collision>
    </link>

    <link name="wheel_rr">
      <inertial>
        <origin xyz="0 0 0" rpy="0 3.141593 0"/>
        <mass value="10.0"/>
        <inertia ixx="0.305583" ixy="0" ixz="0" iyy="0.305583" iyz="0" izz="0.5445"/>
      </inertial>
      <visual name="wheel_rr_visual">
        <origin xyz="0 0 -0.019214" rpy="-1.570796 1.570796 0"/>
        <geometry>
          <mesh filename="package://model_description/meshes/mkz_13/wheel.dae" scale="0.01 0.01 0.01"/>
        </geometry>
        <material name="carpaint_002.002"/>
      </visual>
      <collision name="wheel_rr_collision">
        <origin xyz="0 0 0.0205" rpy="0 3.141593 0"/>
        <geometry>
          <cylinder radius="0.33" length="0.2"/>
        </geometry>
      </collision>
    </link>



    <!-- Camera -->
    <link name="camera_link">
      <collision>
        <origin xyz="0 0 0" rpy="0 0 0"/>
        <geometry>
          <box size="0.05 0.05 0.05"/>
        </geometry>
      </collision>
      <visual>
        <origin xyz="0 0 0" rpy="0 0 0"/>
        <geometry>
          <box size="0.05 0.05 0.05"/>
        </geometry>
      </visual>

      <inertial>
        <origin xyz="0 0 0" rpy="0 0 0"/>
        <mass value="0.1"/>
        <inertia ixx="1" ixy="1" ixz="1.0" iyy="1.0" iyz="1.0" izz="1.0"/>
      </inertial>
    </link>

    <!-- gps -->
    <link name="gps_link">
      <collision>
        <origin xyz="0 0 0" rpy="0 0 0"/>
        <geometry>
          <box size="0.05 0.05 0.05"/>
        </geometry>
      </collision>
      <visual>
        <origin xyz="0 0 0" rpy="0 0 0"/>
        <geometry>
          <box size="0.05 0.05 0.05"/>
        </geometry>
      </visual>

      <inertial>
        <origin xyz="0 0 0" rpy="0 0 0"/>
        <mass value="0.1"/>
        <inertia ixx="1" ixy="1" ixz="1.0" iyy="1.0" iyz="1.0" izz="1.0"/>
      </inertial>
    </link>

  <!-- lidar -->
    <link name="sensor_laser">
    <inertial>
        <origin xyz="0 0 0" rpy="0 0 0"/>
        <mass value="0.1"/>
        <inertia ixx="1" ixy="1" ixz="1.0" iyy="1.0" iyz="1.0" izz="1.0"/>
    </inertial>

    <visual>
        <origin xyz="0 0 0" rpy="0 0 0" />
        <geometry>
        <cylinder radius="0.025" length="0.05"/>
        </geometry>
    </visual>

    <collision>
        <origin xyz="0 0 0" rpy="0 0 0"/>
        <geometry>
        <cylinder radius="0.05" length="0.1"/>
        </geometry>
    </collision>
  </link>





    <joint name="base_link_joint" type="fixed">
      <origin xyz="0 0 0.33" rpy="0 0 0"/>
      <parent link="base_footprint"/>
      <child link="base_link"/>
    </joint>

    <joint name="steer_fl_joint" type="revolute">
      <origin xyz="2.85 0.79121 0.0" rpy="0 0 0"/>
      <parent link="base_link"/>
      <child link="steer_fl"/>
      <axis xyz="0 0 1.0"/>
      <limit lower="-0.6" upper="0.6" effort="0" velocity="0"/>
    </joint>

    <joint name="steer_fr_joint" type="revolute">
      <origin xyz="2.85 -0.79121 0.0" rpy="0 0 0"/>
      <parent link="base_link"/>
      <child link="steer_fr"/>
      <axis xyz="0 0 1.0"/>
      <limit lower="-0.6" upper="0.6" effort="0" velocity="0"/>
    </joint>

    <joint name="wheel_fl_joint" type="continuous">
      <origin xyz="0 0 0" rpy="1.570796 0 -3.141593"/>
      <parent link="steer_fl"/>
      <child link="wheel_fl"/>
      <axis xyz="0 0 1.0"/>
      <limit effort="10" velocity="22.0"/>
    </joint>

    <joint name="wheel_fr_joint" type="continuous">
      <origin xyz="0 0 0" rpy="1.570796 0 -3.141593"/>
      <parent link="steer_fr"/>
      <child link="wheel_fr"/>
      <axis xyz="0 0 1.0"/>
      <limit effort="10" velocity="22.0"/>
    </joint>

    <joint name="wheel_rl_joint" type="continuous">
      <origin xyz="0 0.7874 0" rpy="1.570796 0 -3.141593"/>
      <parent link="base_link"/>
      <child link="wheel_rl"/>
      <axis xyz="0 0 1.0"/>
      <limit effort="50.0" velocity="22.0"/>
    </joint>

    <joint name="wheel_rr_joint" type="continuous">
      <origin xyz="0 -0.7874 0" rpy="1.570796 0 -3.141593"/>
      <parent link="base_link"/>
      <child link="wheel_rr"/>
      <axis xyz="0 0 1.0"/>
      <limit effort="50.0" velocity="22.0"/>
    </joint>








  <joint name="camera_joint" type="fixed">
    <axis xyz="0 1 0" />
    <origin xyz="2.8 0 0.7" rpy="0 0 0"/>
    <parent link="base_link"/>
    <child link="camera_link"/>
  </joint>

  <joint name="joint_sensor_laser" type="fixed">
    <origin xyz="1.5 0 1.1" rpy="0 0 0"/>
    <parent link="base_link"/>
    <child link="sensor_laser"/>
  </joint>

  <joint name="joint_gps" type="fixed">
    <origin xyz="1.5 0 0.2" rpy="0 0 0"/>
    <parent link="base_link"/>
    <child link="gps_link"/>
  </joint>
    
  </robot>